<?xml version="1.0" encoding="UTF-8"?>
<!-- Generated by org.testng.reporters.JUnitReportReporter -->
<testsuite hostname="VE7D00008846" name="com.atdd.demo.runners.RunDemoTest" tests="1" failures="0" timestamp="5 Dec 2018 11:54:21 GMT" time="60.708" errors="1">
  <testcase name="feature" time="60.708" classname="com.atdd.demo.runners.RunDemoTest">
    <error type="cucumber.runtime.CucumberException" message="java.lang.AssertionError: An error has occured while creating a member.Screenshot is captured">
      <![CDATA[cucumber.runtime.CucumberException: java.lang.AssertionError: An error has occured while creating a member.Screenshot is captured
	at cucumber.api.testng.TestNGCucumberRunner.runCucumber(TestNGCucumberRunner.java:69)
	at cucumber.api.testng.AbstractTestNGCucumberTests.feature(AbstractTestNGCucumberTests.java:21)
	at sun.reflect.NativeMethodAccessorImpl.invoke0(Native Method)
	at sun.reflect.NativeMethodAccessorImpl.invoke(NativeMethodAccessorImpl.java:62)
	at sun.reflect.DelegatingMethodAccessorImpl.invoke(DelegatingMethodAccessorImpl.java:43)
	at java.lang.reflect.Method.invoke(Method.java:498)
	at org.testng.internal.MethodInvocationHelper.invokeMethod(MethodInvocationHelper.java:85)
	at org.testng.internal.Invoker.invokeMethod(Invoker.java:639)
	at org.testng.internal.Invoker.invokeTestMethod(Invoker.java:816)
	at org.testng.internal.Invoker.invokeTestMethods(Invoker.java:1124)
	at org.testng.internal.TestMethodWorker.invokeTestMethods(TestMethodWorker.java:125)
	at org.testng.internal.TestMethodWorker.run(TestMethodWorker.java:108)
	at org.testng.TestRunner.privateRun(TestRunner.java:774)
	at org.testng.TestRunner.run(TestRunner.java:624)
	at org.testng.SuiteRunner.runTest(SuiteRunner.java:359)
	at org.testng.SuiteRunner.runSequentially(SuiteRunner.java:354)
	at org.testng.SuiteRunner.privateRun(SuiteRunner.java:312)
	at org.testng.SuiteRunner.run(SuiteRunner.java:261)
	at org.testng.SuiteRunnerWorker.runSuite(SuiteRunnerWorker.java:52)
	at org.testng.SuiteRunnerWorker.run(SuiteRunnerWorker.java:86)
	at org.testng.TestNG.runSuitesSequentially(TestNG.java:1215)
	at org.testng.TestNG.runSuitesLocally(TestNG.java:1140)
	at org.testng.TestNG.run(TestNG.java:1048)
	at org.testng.remote.AbstractRemoteTestNG.run(AbstractRemoteTestNG.java:126)
	at org.testng.remote.RemoteTestNG.initAndRun(RemoteTestNG.java:137)
	at org.testng.remote.RemoteTestNG.main(RemoteTestNG.java:58)
Caused by: java.lang.AssertionError: An error has occured while creating a member.Screenshot is captured
	at org.testng.Assert.fail(Assert.java:94)
	at com.atdd.te.screenHelpers.FunctionalLibrary.CreateMember(FunctionalLibrary.java:370)
	at com.atdd.demo.te.stepdefinitions.helper.CommonStepDefinition.i_create_Member_with(CommonStepDefinition.java:96)
	at âœ½.When I create Member with "SID3340C1","SID3340C1A01","SID3340C1A01G01","test789","LEE","RAYMOND","01011950","010118","123118"(features/RxClaim/featureFiles/SR12345/Test1.feature:8)
]]>
    </error>
  </testcase> <!-- feature -->
</testsuite> <!-- com.atdd.demo.runners.RunDemoTest -->
